Workbook

Sheet README
A1: SAAFAH — Chairman's Business Review Dashboard
A2: Excel data source for the bilingual executive dashboard (data.xlsx)
A4: HOW IT WORKS
A5: 1. Save this file as `data.xlsx` next to the dashboard's `index.html` file.
A6: 2. Edit the BLUE cells only — they are user inputs.
A7: 3. BLACK cells are calculated by formulas; do not overwrite them.
A8: 4. GREEN cells pull from another sheet inside this workbook; do not overwrite them.
A9: 5. Click the REFRESH DATA button on the dashboard (or hard-refresh the browser) after every save.
A10: 6. Each sheet maps to a specific tab/section in the dashboard — see the sheet map below.
A12: COLOUR LEGEND
A13: Blue text | B13: Hardcoded user input — change these freely
A14: Black text | B14: Formula / calculation — do not edit
A15: Green text | B15: Reference to another sheet in this workbook — do not edit
A16: Cream fill | B16: Header / row label
A17: Sand fill | B17: Subtotal / total row
A20: SHEET MAP
A21: Sheet | B21: Dashboard Section | C21: Notes
A22: Financial_Overview | B22: Tab: Financial Overview | C22: P&L summary by quarter; KPIs auto-derived.
A23: Cash_Flow | B23: Tab: Cash Flow | C23: Cash-flow waterfall by quarter; KPIs auto-derived.
A24: Strategy_Operations | B24: Tab: Strategy & Operations | C24: Loaded but only Operations Readiness card is shown on dashboard.
A25: Pipeline_Revenue | B25: Tab: Pipeline & Revenue | C25: Monthly revenue ramp + collections; KPIs auto-derived.
A26: Sales_Performance | B26: Tab: Sales Performance — KPI strip | C26: Counts and values by stage; auto-derived from raw opportunities.
A27: Sales_Raw_Opportunities | B27: Tab: Sales Performance — Opportunities Register table & Funnel | C27: Single source of truth for every proposal/lead/won/lost record.
A28: Sales_Raw_Operations | B28: Internal — operations items (legacy) | C28: Optional; safe to leave empty.
A29: Sales_Stage_Details | B29: KPI tooltip drilldowns (week / month detail) | C29: One row per record per period; powers the hover/click tooltip.

Sheet Financial_Overview
A1: FINANCIAL OVERVIEW — FY 2026
A2: Drives the Financial Overview tab. Inputs in BLUE; formulas and links in BLACK/GREEN.
A4: KPI | B4: Value | C4: Unit | D4: Notes
A5: Revenue 2026 | B5: =F11 -> 2273750 | C5: SAR | D5: Year total from P&L (link)
A6: Gross Profit 2026 | B6: =F13 -> 948875 | C6: SAR | D6: Gross Profit year total (link)
A7: Net P/L 2026 | B7: =F16 -> -1773814.6 | C7: SAR | D7: Net Profit / Loss year total (link)
A8: Overheads 2026 | B8: =ABS(F15) -> 2722689.6 | C8: SAR | D8: Overheads year total (link, shown as positive number)
A10: Description | B10: Q1 | C10: Q2 | D10: Q3 | E10: Q4 | F10: Year 2026
A11: Revenue | B11: 0 | C11: 330000 | D11: 906750 | E11: 1037000 | F11: =SUM(B11:E11) -> 2273750
A12: Cost of Revenue | B12: 0 | C12: -198000 | D12: -525375 | E12: -601500 | F12: =SUM(B12:E12) -> -1324875
A13: Gross Profit | B13: =B11+B12 -> 0 | C13: =C11+C12 -> 132000 | D13: =D11+D12 -> 381375 | E13: =E11+E12 -> 435500 | F13: =F11+F12 -> 948875 | I13: -1
A14: GP % | B14: =IFERROR(B13/B11,0) -> 0 | C14: =IFERROR(C13/C11,0) -> 0.4 | D14: =IFERROR(D13/D11,0) -> 0.42059553 | E14: =IFERROR(E13/E11,0) -> 0.41996143 | F14: =IFERROR(F13/F11,0) -> 0.41731721
A15: Overheads | B15: -670413.09 | C15: -637944.99 | D15: -656001.9 | E15: -758329.67 | F15: =SUM(B15:E15) -> -2722689.6
A16: Net Profit / Loss | B16: =B13+B15 -> -670413.09 | C16: =C13+C15 -> -505944.99 | D16: =D13+D15 -> -274626.9 | E16: =E13+E15 -> -322829.67 | F16: =F13+F15 -> -1773814.6

Sheet Cash_Flow
A1: CASH FLOW — FY 2026
A2: Drives the Cash Flow tab. Cash flow is calculated by Excel — only adjust BLUE inputs.
A4: KPI | B4: Value | C4: Unit | D4: Notes
A5: Opening Balance | B5: =B11 -> 581455.34 | C5: SAR | D5: Q1 opening (input)
A6: Total Cash Inflow | B6: =F15 -> 1822062.5 | C6: SAR | D6: Sum of advisory + training collections
A7: Total Cash Outflow | B7: =F16+F17 -> -4047564.6 | C7: SAR | D7: Cost of Revenue + G&A (negative)
A8: Closing Balance | B8: =F19 -> -1644046.8 | C8: SAR | D8: Year-end cash position
A10: Description | B10: Q1 | C10: Q2 | D10: Q3 | E10: Q4 | F10: Year 2026
A11: Opening Balance | B11: 581455.34 | C11: -88957.75 | D11: -736902.74 | E11: -1311092.1 | F11: =B11 -> 581455.34
A12: Advisory Collections | B12: 0 | C12: 0 | D12: 400000 | E12: 560000 | F12: =SUM(B12:E12) -> 960000
A13: Mentorship Program | B13: 0 | C13: 188000 | D13: 150000 | E13: 270000 | F13: =SUM(B13:E13) -> 608000
A14: Training Collections | B14: 0 | C14: 0 | D14: 57187.5 | E14: 196875 | F14: =SUM(B14:E14) -> 254062.5
A15: Total Cash Inflow | B15: =SUM(B12:B14) -> 0 | C15: =SUM(C12:C14) -> 188000 | D15: =SUM(D12:D14) -> 607187.5 | E15: =SUM(E12:E14) -> 1026875 | F15: =F12+F14+F13 -> 1822062.5
A16: Cost of Revenue | B16: 0 | C16: -198000 | D16: -507375 | E16: -601500 | F16: =Financial_Overview!F12 -> -1324875
A17: G&A Expenses | B17: =Financial_Overview!B15 -> -670413.09 | C17: =Financial_Overview!C15 -> -637944.99 | D17: =Financial_Overview!D15 -> -656001.9 | E17: =Financial_Overview!E15 -> -758329.67 | F17: =Financial_Overview!F15 -> -2722689.6
A18: Net Cash Flow | B18: =B15+B16+B17 -> -670413.09 | C18: =C15+C16+C17 -> -647944.99 | D18: =D15+D16+D17 -> -556189.4 | E18: =E15+E16+E17 -> -332954.67 | F18: =F15+F16+F17 -> -2225502.1
A19: Closing Balance | B19: =B18+B11 -> -88957.75 | C19: =C18+C11 -> -736902.74 | D19: =D18+D11 -> -1293092.1 | E19: =E18+E11 -> -1644046.8 | F19: =E19 -> -1644046.8
A20: Cash Injection Required | B20: =IF(B19<0,B19,0) -> -88957.75 | C20: =IF(C19<0,C19,0) -> -736902.74 | D20: =IF(D19<0,D19,0) -> -1293092.1 | E20: =IF(E19<0,E19,0) -> -1644046.8 | F20: =E20 -> -1644046.8

Sheet Pipeline_Revenue
A1: PIPELINE & REVENUE — FY 2026
A2: Monthly revenue ramp + collection schedule. KPIs auto-derived from the data tables below.
A4: Metric | B4: Value | C4: Notes
A5: Total Revenue Pipeline 2026 | B5: =E24 -> 1822062.5 | C5: Year Total of monthly Total Revenue (link to row 23)
A6: Proposals Q1–Q2 2026 | B6: =SUMIFS(H12:H22,F12:F22,"Q1")+SUMIFS(H12:H22,F12:F22,"Q2") -> 1970000 | C6: Sum of Proposal Value where Quarter = Q1 or Q2
A7: Active Proposals | B7: =COUNTA(G12:G22) -> 9 | C7: Count of clients with proposals in monthly ramp
A10: Month | B10: Advisory Revenue | C10: Training Revenue | D10: Mentorship Program Revenue | E10: Total Revenue | F10: Quarter | G10: Client | H10: Proposal Value (SAR) | I10: Notes | J10: Reserved
A12: Jan | E12: =B12+C12+D12 -> 0 | F12: Q1 | G12: NADEC | H12: 500000
A13: Feb | E13: =B13+C13+D13 -> 0 | F13: Q1 | G13: MEP | H13: 500000
A14: Mar | E14: =B14+C14+D14 -> 0 | F14: Q1 | G14: ITQAN ESG | H14: 350000
A15: Apr | E15: =B15+C15+D15 -> 0 | F15: Q2 | G15: TADAWUL | H15: 330000
A16: May | B16: 80000 | C16: 86250 | E16: =B16+C16+D16 -> 166250 | F16: Q2 | G16: MDL BEAST | H16: 220000
A17: Jun | B17: 160000 | C17: 101750 | E17: =B17+C17+D17 -> 261750 | F17: Q2 | G17: OBEKAN | H17: 70000
A18: Jul | B18: 160000 | C18: 30000 | E18: =B18+C18+D18 -> 190000 | F18: Q3 | G18: YAMAMA CEMENT | H18: 50000
A19: Aug | B19: 160000 | C19: 60000 | E19: =B19+C19+D19 -> 220000 | F19: Q3 | G19: PIF — CFG | H19: 45000
A20: Sep | B20: 160000 | C20: 60000 | D20: 57187.5 | E20: =B20+C20+D20 -> 277187.5 | F20: Q3 | G20: Financial Academy | H20: 30000
A21: Oct | B21: 240000 | C21: 90000 | D21: 62250 | E21: =B21+C21+D21 -> 392250 | F21: Q4
A22: Nov | C22: 90000 | D22: 67312.5 | E22: =B22+C22+D22 -> 157312.5 | F22: Q4
A23: Dec | C23: 90000 | D23: 67312.5 | E23: =B23+C23+D23 -> 157312.5 | F23: Q4
A24: Year Total | B24: =SUM(B12:B23) -> 960000 | C24: =SUM(C12:C23) -> 608000 | D24: =SUM(D12:D23) -> 254062.5 | E24: =SUM(E12:E23) -> 1822062.5 | H24: =SUM(H12:H22) -> 2095000
A27: Description | B27: Q1 | C27: Q2 | D27: Q3 | E27: Q4 | F27: Year 2026
A28: Total Collections | B28: =B29+B31 -> 0 | C28: =C29+C31 -> 428000 | D28: =D29+D31 -> 630000 | E28: =E29+E31 -> 510000 | F28: =F29+F31+F30 -> 1822062.5
A29: Advisory Collections | B29: 0 | C29: =SUM(B15:B17) -> 240000 | D29: =SUM(B18:B20) -> 480000 | E29: =SUM(B21:B23) -> 240000 | F29: =SUM(B29:E29) -> 960000
A30: Mentorship Programs | C30: =SUM(D15:D17) -> 0 | D30: =SUM(D18:D20) -> 57187.5 | E30: =SUM(D21:D23) -> 196875 | F30: =SUM(B30:E30) -> 254062.5
A31: Training Collections | B31: 0 | C31: =SUM(C15:C17) -> 188000 | D31: =SUM(C18:C20) -> 150000 | E31: =SUM(C21:C23) -> 270000 | F31: =SUM(B31:E31) -> 608000
B37: 80000 | C37: 86250 | D37: 57187.5 | E37: 86250 | F37: 101750 | G37: 30000 | H37: 60000 | I37: 60000 | J37: 90000 | K37: 90000 | L37: 90000
B38: 160000 | C38: 101750 | D38: 62250 | E38: 57187.5 | F38: 62250 | G38: 67312.5 | H38: 67312.5
B39: 160000 | C39: 30000 | D39: 67312.5
B40: 160000 | C40: 60000 | D40: 67312.5
B41: 160000 | C41: 60000
B42: 240000 | C42: 90000
C43: 90000
C44: 90000

Sheet Sales_Performance
A1: SALES PERFORMANCE — KPI Strip | I1: 46126
A2: All counts and values are auto-derived from Sales_Raw_Opportunities by stage.
A4: Metric | B4: Count | C4: Value_SAR | D4: This_Month_Count | E4: This_Month_Value_or_Note | F4: This_Week_Count | G4: This_Week_Value_or_Note | H4: Insight Title | I4: Insight Detail
A5: Total Leads | B5: =COUNTIF(Sales_Stage_Details!A:A,"Lead") -> 8 | C5: =SUMIF(Sales_Stage_Details!A:A,"Lead",Sales_Stage_Details!E:E) -> 450000 | D5: =B5 -> 8 | E5: =C5 -> 450000 | F5: =COUNTIFS(Sales_Stage_Details!A5:A193,"Lead",Sales_Stage_Details!B5:B193,"This Week") -> 8 | G5: =SUMIFS(Sales_Stage_Details!E5:E193,Sales_Stage_Details!A5:A193,"Lead",Sales_Stage_Details!B5:B193,"This Week") -> 450000
A6: Active Proposals | B6: =COUNTIF(Sales_Raw_Opportunities!I4:I999,"Active Proposal") -> 0 | C6: =SUMIFS(Sales_Raw_Opportunities!F4:F999,Sales_Raw_Opportunities!I4:I999,"Active Proposal") -> 0 | D6: =SUMPRODUCT((Sales_Raw_Opportunities!I4:I999="Active Proposal")*(Sales_Raw_Opportunities!D4:D999=TEXT(TODAY(),"mmm yyyy"))) -> 0 | F6: =COUNTIFS(Sales_Stage_Details!A5:A193,"Active Proposal",Sales_Stage_Details!B5:B193,"This Week") -> 0 | G6: =SUMIFS(Sales_Stage_Details!E5:E193,Sales_Stage_Details!A5:A193,"Active Proposal",Sales_Stage_Details!B5:B193,"This Week") -> 0
A7: Proposals Submitted | B7: =COUNTIF(Sales_Raw_Opportunities!I4:I999,"Submitted") -> 5 | C7: =SUMIFS(Sales_Raw_Opportunities!F4:F999,Sales_Raw_Opportunities!I4:I999,"Submitted") -> 1365000 | D7: =SUMPRODUCT((Sales_Raw_Opportunities!I4:I999="Submitted")*(Sales_Raw_Opportunities!D4:D999=TEXT(TODAY(),"mmm yyyy"))) -> 0 | E7: =SUMIFS( Sales_Raw_Opportunities!F:F, Sales_Raw_Opportunities!I:I,"Submitted", Sales_Raw_Opportunities!D:D,">"&Sales_Performance!I1 ) -> 85000 | F7: =COUNTIFS(Sales_Stage_Details!A5:A193,"Submitted",Sales_Stage_Details!B5:B193,"This Week") -> 0 | G7: =SUMIFS(Sales_Stage_Details!E5:E193,Sales_Stage_Details!A5:A193,"Submitted",Sales_Stage_Details!B5:B193,"This Week") -> 0
A8: Won This Year | B8: =COUNTIF(Sales_Raw_Opportunities!I4:I999,"Won") -> 4 | C8: =SUMIFS(Sales_Raw_Opportunities!F4:F999,Sales_Raw_Opportunities!I4:I999,"Won") -> 165000 | D8: =SUMPRODUCT((Sales_Raw_Opportunities!I4:I999="Won")*(Sales_Raw_Opportunities!D4:D999=TEXT(TODAY(),"mmm yyyy"))) -> 0 | E8: 0 | F8: =COUNTIFS(Sales_Stage_Details!A5:A193,"Won",Sales_Stage_Details!B5:B193,"This Week") -> 0 | G8: =SUMIFS(Sales_Stage_Details!E5:E193,Sales_Stage_Details!A5:A193,"Won",Sales_Stage_Details!B5:B193,"This Week") -> 0
A9: Lost This Year | B9: =COUNTIF(Sales_Raw_Opportunities!I4:I999,"Lost") -> 4 | C9: =SUMIFS(Sales_Raw_Opportunities!F4:F999,Sales_Raw_Opportunities!I4:I999,"Lost") -> 355000 | D9: =SUMPRODUCT((Sales_Raw_Opportunities!I4:I999="Lost")*(Sales_Raw_Opportunities!D4:D999=TEXT(TODAY(),"mmm yyyy"))) -> 0 | E9: =SUMIFS( Sales_Raw_Opportunities!F:F, Sales_Raw_Opportunities!I:I,"Lost") -> 355000 | F9: =COUNTIFS(Sales_Stage_Details!A5:A193,"Lost",Sales_Stage_Details!B5:B193,"This Week") -> 0 | G9: =SUMIFS(Sales_Stage_Details!E5:E193,Sales_Stage_Details!A5:A193,"Lost",Sales_Stage_Details!B5:B193,"This Week") -> 0
A12: ⓘ All values above are auto-calculated from Sales_Raw_Opportunities and Sales_Stage_Details. Edit those sheets to update KPIs.

Sheet Sales_Raw_Opportunities
A1: SALES — OPPORTUNITIES REGISTER
A2: Single source of truth for every proposal/lead/won/lost. KPIs and Funnel are derived from this table.
A3: Client | B3: Opportunity | C3: BD Lead | D3: Submitted | E3: Won Date | F3: Value_SAR | G3: Probability_Pct | H3: Weighted_Value_SAR | I3: Stage | J3: Notes
A4: Financial Academy | B4: ESG and Corporate Governance Enablement | C4: Gihan Hyde | D4: 45894 | F4: 45000 | G4: 0 | H4: =IF(AND(ISNUMBER(F4),ISNUMBER(G4)),F4*G4,"") -> 0 | I4: Lost
A5: Financial Academy | B5: ESG Workshop | C5: Gihan Hyde | D5: 45988 | F5: 140000 | G5: 0 | H5: =IF(AND(ISNUMBER(F5),ISNUMBER(G5)),F5*G5,"") -> 0 | I5: Lost
A6: ITQAN | B6: ESG Workshop | C6: Gihan Hyde | D6: 45935 | F6: 400000 | G6: 0.3 | H6: =IF(AND(ISNUMBER(F6),ISNUMBER(G6)),F6*G6,"") -> 120000 | I6: Active
A7: MEP | B7: Acceselerating Success for the KSA Sustainability Champions Program | C7: Gihan Hyde | D7: 46000 | F7: 500000 | G7: 0.85 | H7: =IF(AND(ISNUMBER(F7),ISNUMBER(G7)),F7*G7,"") -> 425000 | I7: Submitted | J7: No Payment, Marketing Purpouse
A8: Middle Beast | B8: Attache ESG Enablement | C8: Gihan Hyde | D8: 46083 | F8: 100000 | G8: 0.5 | H8: =F8*G8 -> 50000 | I8: Submitted
A9: NADEC | B9: ESG Integration | C9: Gihan Hyde | D9: 46054 | F9: 500000 | G9: 0.5 | H9: =F9*G9 -> 250000 | I9: Submitted
A10: Obeikan | B10: RPI ESG Workshop | C10: Gihan Hyde | D10: 45991 | F10: 70000 | G10: 0 | H10: =IF(AND(ISNUMBER(F10),ISNUMBER(G10)),F10*G10,"") -> 0 | I10: Lost
A11: PIF | B11: PIF Offsite Proposal | C11: Gihan Hyde | D11: 46015 | F11: 100000 | G11: 0 | H11: =IF(AND(ISNUMBER(F11),ISNUMBER(G11)),F11*G11,"") -> 0 | I11: Lost
A12: Center For Government | B12: ESG and Sustainability Course Development | C12: Gihan Hyde | D12: 45942 | F12: 68000 | G12: 0.5 | H12: =F12*G12 -> 34000 | I12: On Hold
A13: Center For Government | B13: Monshaat ESG Course | C13: Gihan Hyde | D13: 46120 | F13: 20000 | G13: 0.8 | H13: =F13*G13 -> 16000 | I13: Active
A14: SIDF | B14: ESG Workshop | C14: Gihan Hyde | D14: 45922 | F14: 75000 | G14: 0 | H14: =F14*G14 -> 0 | I14: Won
A15: Tadawul Group | B15: ESG and Corporate Governance Graduate Enablement | C15: Gihan Hyde | D15: 45890 | F15: 0 | G15: 0.5 | H15: =F15*G15 -> 0 | I15: On hold
A16: Tadawul Group | B16: AI In Action | C16: Gihan Hyde | D16: 46047 | F16: 90000 | G16: 0.5 | H16: =IF(AND(ISNUMBER(F16),ISNUMBER(G16)),F16*G16,"") -> 45000 | I16: On hold
A17: Tadawul Group | B17: GDP ESG Workshop | C17: Gihan Hyde | D17: 45958 | F17: 60000 | G17: 0.5 | H17: =F17*G17 -> 30000 | I17: On hold
A18: CMA | B18: Sustainable Finance /MEP Campaign | C18: Gihan Hyde | D18: 46091 | F18: 0 | G18: 0.5 | H18: =F18*G18 -> 0 | I18: Won | J18: 100%, no Payment from the Client/Marketing Purpouse-Gihan will be the host
A19: Financial Academy | B19: ESG Certificate | C19: Gihan Hyde | D19: 46040 | E19: 46055 | F19: 30000 | G19: 1 | H19: =IF(AND(ISNUMBER(F19),ISNUMBER(G19)),F19*G19,"") -> 30000 | I19: Won
A20: Humain | B20: AI & Governance | C20: Gihan Hyde | F20: 500000 | G20: 0.4 | H20: =F20*G20 -> 200000 | I20: Active
A21: Expo | B21: Community Education | C21: Gihan Hyde | F21: 700000 | G21: 0.5 | H21: =IF(AND(ISNUMBER(F21),ISNUMBER(G21)),F21*G21,"") -> 350000 | I21: Active
A22: Riyadh Air | B22: Anti Money laundry /Fraud Cousre | C22: Gihan Hyde | D22: april 26th | F22: 60000 | G22: 0.6 | H22: =IF(AND(ISNUMBER(F22),ISNUMBER(G22)),F22*G22,"") -> 36000 | I22: Won
A23: Nestle | B23: ESG Academy | C23: Gihan Hyde | F23: 200000 | G23: 0.3 | H23: =IF(AND(ISNUMBER(F23),ISNUMBER(G23)),F23*G23,"") -> 60000 | I23: Active
A24: KPMG | B24: Environmental Training | C24: Gihan Hyde | F24: 100000 | G24: 0.3 | H24: =IF(AND(ISNUMBER(F24),ISNUMBER(G24)),F24*G24,"") -> 30000 | I24: Active
A25: NCFB | B25: Mentorship Program | C25: Gihan Hyde | F25: 180000 | G25: 0.6 | H25: =IF(AND(ISNUMBER(F25),ISNUMBER(G25)),F25*G25,"") -> 108000 | I25: Submitted
A26: Gosi-Mentorship | B26: Mentorship Platfrom | C26: Gihan Hyde | D26: 46131 | F26: 85000 | G26: 0.8 | H26: =IF(AND(ISNUMBER(F26),ISNUMBER(G26)),F26*G26,"") -> 68000 | I26: Submitted
A27: Alinma Bank | B27: Governance Training & Social Imapct Measurment | H27: 70000 | I27: Lead
A28: SABIC | B28: MEP Sustanability Champion Support | H28: 50000 | I28: Lead
A29: Kaplan | B29: ESG Training Certification Partnership | H29: 50000 | I29: Lead
A30: CMA(Fintech) | B30: Supporting Fentec Saudi on Sustainable Investment | H30: 10000 | I30: Lead
A31: Avilease | H31: 10000 | I31: Lead
A32: The National Company for Mechanical Systems (NCMS) الشركة الوطنية للأنظمة الميكانيكية | B32: Governance Framework Advisory | H32: 200000 | I32: Lead
A33: Saudi Global Ports | B33: Governance Training & ESG Advisory | H33: 10000 | I33: Lead
A34: Savvy Group ( PIF | B34: Mentorship | H34: 50000 | I34: Lead
H35: =IF(AND(ISNUMBER(F35),ISNUMBER(G35)),F35*G35,"")
H36: =IF(AND(ISNUMBER(F36),ISNUMBER(G36)),F36*G36,"")
H37: =IF(AND(ISNUMBER(F37),ISNUMBER(G37)),F37*G37,"")
H38: =IF(AND(ISNUMBER(F38),ISNUMBER(G38)),F38*G38,"")
H39: =IF(AND(ISNUMBER(F39),ISNUMBER(G39)),F39*G39,"")
H40: =IF(AND(ISNUMBER(F40),ISNUMBER(G40)),F40*G40,"")
...

Sheet Sales_Stage_Details
A1: SALES — STAGE DETAILS (KPI Tooltip Drill-Down)
A2: One row per record per period. Period must be exactly 'This Week' or 'This Month'.
A4: Stage | B4: Period | C4: Client | D4: Opportunity | E4: Value_ | F4: Owner | G4: Notes
A5: Lead | B5: This Week | C5: Alinma Bank | D5: Governance Training & Social Imapct Measurment | E5: 70000
A6: Lead | B6: This Week | C6: SABIC | D6: MEP Sustanability Champion Support | E6: 50000
A7: Lead | B7: This Week | C7: Kaplan | D7: ESG Training Certification Partnership | E7: 50000
A8: Lead | B8: This Week | C8: CMA(Fintech) | D8: Supporting Fentec Saudi on Sustainable Investment | E8: 10000
A9: Lead | B9: This Week | C9: Avilease | E9: 10000
A10: Lead | B10: This Week | C10: The National Company for Mechanical Systems (NCMS) الشركة الوطنية للأنظمة الميكانيكية | D10: Governance Framework Advisory | E10: 200000
A11: Lead | B11: This Week | C11: Saudi Global Ports | D11: Governance Training & ESG Advisory | E11: 10000
A12: Lead | B12: This Week | C12: Savvy Group ( PIF | D12: Mentorship | E12: 50000

Sheet Sales_Raw_Operations
A1: SALES — OPERATIONS ITEMS
A2: Optional. The dashboard reads this but does not currently render any visible component from it.
A3: Operation Item | B3: Status | C3: Progress_Pct
A4: Bank Account Activation | B4: Done | C4: 1
A5: National Address | B5: Done | C5: 1
A6: External Audit+Zakat Return (2025) | B6: Inprogress | C6: 0.75
A7: Website | B7: Inprogress | C7: 0.6
A8: Advisory Committee | B8: Inprogress | C8: 0.5
A9: Governance Policies | B9: Inprogress | C9: 0.5
A10: Recruitment | B10: Inprogress | C10: 0.8
A11: Advisory Committee | B11: Inprogress | C11: 0.4
A12: Commercial Registration(Profit Org) | B12: Inprogress | C12: 0.2
A13: ZATCA update (2011-2018) | B13: Done | C13: 1
A14: ZATCA update (2019-2024) | B14: Inprogress | C14: 0.7
A15: ZATCA update (2025)-External Auditor | B15: Inprogress | C15: 0.7
... A17: Saafah Ehtimad on Boarding | B17: Inprogress | C17: 0.7

Sheet Strategy_Operations
A1: STRATEGY & OPERATIONS
A2: Most of this sheet is no longer rendered on the dashboard (only Operations Readiness card remains).
A4: Section | B4: Content
A5: Operation Motive in Saudi Society | B5: Supporting community welfare and social development — encouraging volunteerism and community participation. Contributing to national development goals aligned with Saudi Vision 2030, promoting transparency and accountability under the National Center for Non-Profit Sector.
A8: Pillar | B8: Description | C8: Category | D8: Revenue (SAR) | E8: Share | F8: Reserved | G8: Reserved
A9: Advisory Services | B9: Strategic advisory for government and non-government sectors | C9: Advisory | D9: 1828426 | E9: 0.6
A10: Training Courses | B10: Specialized training programs for institutional capacity building | C10: Training | D10: 1218950 | E10: 0.4
A11: Innovation & Technology | B11: Scalable, compliant, technology-driven solutions for social impact | D11: 0 | E11: 0
A13: Sector | B13: Key Point 1 | C13: Key Point 2
A14: Government Sector | B14: Training, advisory, and innovation support to government institutions | C14: Leverage regulatory compliance, public sector programs, and government partnerships
A15: Non-Government Sector | B15: Engage NGOs, private foundations, and social enterprises | C15: Tailored programs in advisory, innovation, and technology services
A18: Type | B18: Detail
A19: Approach 1 | B19: Map key government agencies and NGOs aligned with mission
A20: Approach 2 | B20: Develop sector-specific solutions and service packages
A21: Approach 3 | B21: Strengthen relationships via workshops, consultations, and pilot projects
A22: Goal 1 | B22: Position as a trusted partner for government and non-government sectors
A23: Goal 2 | B23: Expand reach, credibility, and impact by year-end
A26: Type | B26: Detail
A27: VP 1 | B27: Act as a bridge between government initiatives and community/non-profit impact
A28: VP 2 | B28: Provide specialized services that are compliant, innovative, and scalable
A29: VP 3 | B29: Advisory drives 60% of revenue — high-margin strategic consulting
A30: VP 4 | B30: Training at 40% — scalable capacity building with recurring revenue potential
